Workbook
Name Slicer_Capturing_Official: #N/A
Name Slicer_Department: #N/A
Name Slicer_Location: #N/A
Name Slicer_Service: #N/A

Sheet citizen_services_records_log
A1: Case Reference | B1: Date Captured | C1: Service Type | D1: Branch/Office | E1: Applicant Full Name | F1: ID Number | G1: Date of Birth | H1: Gender | I1: Contact Number | J1: Ward/Area | K1: Grant Type | L1: Document Status | M1: Processing Status | N1: Queue/Ticket Number | O1: Capturing Official | P1: Follow-Up Date | Q1: Notes
A2: sassa-000796 | B2: 14/05/2026 | C2: SASSA Grant Application | D2: Sharpeville Clinic | E2: Nomvula Fourie | F2: 8500000000000 | G2: 31160 | H2: Male | I2: (072) 2913562 | J2: Ward 20 | K2: Older Person's Grant | L2: Pending Verification | M2: Resolved | N2: Q137 | O2: Werner Meyer | P2: 46175 | Q2: System offline - captured manually, will upload later
A3: DHA001034 | B3: 15-04-2026 | C3: Home Affairs - Passport Application | D3: Vanderbijlpark Home Affairs | E3: Marie Van der Merwe | F3: 7910000000000 | G3: 29118 | H3: M | I3: 067 773 4000 | J3: Ward 18 | L3: Under Review | M3: CAPTURED | N3: Q008 | O3: Lerato Mahlangu | Q3: Grant payment query - referred to SASSA call centre | W3: =LEN(ISTEXT(A2))+1 -> 5
A4: MUN-000761 | B4: 16/09/2026 | C4: Municipal - Service Request | D4: Vanderbijlpark Home Affairs | E4: Nomvula Pretorius | G4: 30487 | H4: F | I4: 27811757562 | J4: Ward 7 | M4: Closed | N4: Q055 | O4: Refilwe Khumalo
A5: dha-000959 | B5: 46234 | C5: Home Affairs - Birth Certificate | D5: Emfuleni Municipal Office | E5: Marie Mokgadi | H5: Male | I5: 075-123-0616 | J5: Ward 6 | L5: COMPLETE | M5: Awaiting Documents | N5: Q244 | O5: Refilwe Nel
A6: SASSA000603 | B6: 46093 | C6: SASSA Grant Application | D6: Emfuleni Municipal Office | E6: Grace Steyn | G6: 16512 | H6: male | I6: 076 711 8567 | J6: Ward 20 | K6: Social Relief of Distress (SRD) | M6: Escalated | N6: Q211 | O6: Lerato Nel | Q6: Urgent case - fast-tracked per supervisor approval
A7: CLN-000736 | B7: 46226 | C7: Clinic - Chronic Medication Collection | D7: Vanderbijlpark Home Affairs | E7: Dorah Mokoena | F7: 7110000000000 | G7: 26004 | H7: F | I7: 27818399641 | J7: Ward 23 | L7: Under Review | M7: Resolved | N7: Q094 | O7: Andries Meyer | Q7: Applicant is a minor, guardian present and documented
A8: MUN-000968 | B8: 46198 | C8: Municipal - Account Query | D8: Vereeniging Home Affairs | E8: Sipho Mokgadi | F8: 207000000000 | G8: 37454 | H8: F | I8: 073-333-3031 | J8: Ward 11 | L8: complete | M8: CAPTURED | N8: Q186 | O8: Andries Mahlangu | Q8: Home Affairs system down for maintenance during visit
A9: MUN000202 | B9: 46297 | C9: Municipal - Account Query | D9: Meyerton Municipal Office | E9: TUMELO NDLOVU | F9: 203000000000 | G9: 28-03-2002 | H9: F | I9: 074-547-7794 | J9: Ward 16 | L9: Pending Verification | M9: Awaiting Documents | N9: Q096 | O9: Werner Nel | P9: 46077
A10: dha-000061 | B10: 46051 | C10: Home Affairs - Passport Application | D10: Three Rivers Clinic | E10: Nomvula Sithole | F10: 7610000000000 | H10: Female | I10: (075) 5515861 | J10: Ward 12 | L10: Incomplete - Missing Proof of Residence | M10: CAPTURED | N10: Q011 | O10: Chris Khumalo | P10: 22/02/2026 | Q10: Incorrect ID number provided initially, corrected
A11: CLN000452 | B11: 46084 | C11: Clinic - General Consultation | D11: Vanderbijlpark Home Affairs | E11: Nomvula Khumalo | F11: 4800000000000 | H11: female | I11: (067) 9956360 | J11: Ward 3 (Informal Settlement) | L11: complete | M11: Re-opened | N11: Q040 | Q11: System offline - captured manually, will upload later
A12: DHA000449 | B12: 46000 | C12: Home Affairs - Death Certificate | D12: Meyerton Municipal Office | E12: Zodwa Steyn | F12: 4800000000000 | G12: 17620 | H12: M | I12: 067-990-1527 | J12: Ward 15 | L12: Awaiting Home Affairs Confirmation | M12: Re-opened | N12: Q075 | O12: Marius Swart | P12: 22/12/2025 | Q12: Biometric capture failed, rescheduled
A13: mun-000359 | B13: 46051 | C13: Municipal - Account Query | D13: Emfuleni Municipal Office | E13: Dorah Nkosi | F13: 6210000000000 | G13: 22834 | H13: Male | I13: 27621656883 | J13: Ward 23 | L13: Approved | M13: Awaiting Documents | N13: Q029 | O13: Marius Sithole | Q13: Applicant referred to social worker
A14: MUN-000345 | B14: 46192 | C14: Municipal - Service Request | D14: Meyerton Municipal Office | E14: Nokuthula Radebe | F14: 78081164081 | G14: 28802 | H14: Male | I14: 633367127 | J14: Ward 23 | L14: Rejected | M14: Awaiting Documents | N14: Q248 | O14: Busisiwe Nel | Q14: Applicant is a minor, guardian present and documented
A15: SASSA000493 | B15: 46210 | C15: SASSA Grant Application | D15: Sebokeng SASSA Office | E15: Mandla Mokoena | F15: 5110000000000 | G15: 29-10-1951 | I15: 27636243912 | J15: Ward 2 | K15: Disability Grant | L15: Under Review | M15: CAPTURED | N15: Q282 | O15: Palesa Coetzee | Q15: Interpreter required - assisted in Sesotho
A16: MUN000510 | B16: 46162 | C16: Municipal - Account Query | D16: Boipatong Clinic | E16: Grace Kruger | F16: 8700000000000 | G16: 31826 | I16: 602893436 | J16: Ward 18 | L16: Complete | M16: Awaiting Documents | N16: Q282 | O16: Chris Swart | Q16: Grant payment query - referred to SASSA call centre
A17: mun-000427 | B17: 46114 | C17: Municipal - Service Request | D17: Meyerton Municipal Office | E17: thabo ndlovu | F17: 706000000000 | G17: 39241 | H17: Male | I17: 079 131 5470 | J17: Ward 14 | L17: Pending Verification | M17: Pending | N17: Q105 | O17: Palesa Khumalo | P17: 46119 | Q17: Urgent case - fast-tracked per supervisor approval
A18: SASSA000545 | B18: 25/07/2026 | C18: SASSA Grant Application | D18: Sebokeng SASSA Office | F18: 9110000000000 | G18: 33408 | H18: male | I18: 062-936-6785 | J18: Ward 18 | K18: Disability Grant | L18: Approved | M18: Re-opened | N18: Q210 | O18: Andries Sithole | Q18: System offline - captured manually, will upload later
A19: MUN-001037 | B19: 27/02/2026 | C19: Municipal - Account Query | D19: Sasolburg Home Affairs | E19: Lindiwe Khumalo | F19: 5210000000000 | G19: 19133 | H19: female | I19: 074 110 9152 | J19: Ward 5 | L19: Awaiting Home Affairs Confirmation | M19: Resolved | N19: Q214 | O19: Andries Sithole | Q19: Biometric capture failed, rescheduled
A20: DHA000087 | B20: 30-04-2026 | C20: Home Affairs - ID Application | D20: Emfuleni Municipal Office | E20: Lindiwe Khumalo | F20: 6110000000000 | G20: 22635 | H20: male | I20: N/A | J20: Ward 23 | L20: Awaiting Home Affairs Confirmation | M20: captured | O20: Palesa Swart | P20: 29-05-2026 | Q20: Follow-up call required to confirm banking details
A21: DHA000894 | B21: 46080 | C21: Home Affairs - ID Application | D21: Vereeniging Home Affairs | E21: Nokuthula Dlamini | G21: 30603 | H21: Female | I21: 061 858 5722 | J21: Ward 13 | L21: Pending Verification | M21: Closed | N21: Q167 | O21: Busisiwe Mahlangu | P21: 46176 | Q21: Grant payment query - referred to SASSA call centre
A22: DHA000904 | B22: 46237 | C22: Home Affairs - Death Certificate | D22: Vereeniging Home Affairs | E22: Thabo Botha | F22: 103000000000 | G22: 36968 | H22: Female | I22: 27622853681 | J22: Ward 19 | L22: Under Review | M22: CAPTURED | N22: Q104 | O22: Marius Meyer | Q22: Follow-up call required to confirm banking details
A23: DHA000470 | B23: 46084 | C23: Home Affairs - ID Application | D23: Vanderbijlpark Home Affairs | E23: Sizwe Ndlovu | F23: 6210000000000 | G23: 22867 | H23: female | I23: 081 452 6015 | J23: Ward 15 | L23: Pending Verification | M23: Awaiting Documents | N23: Q052 | O23: Marius Mahlangu | P23: 46103 | Q23: Applicant is a minor, guardian present and documented
A24: mun-000912 | B24: 46276 | C24: Municipal - Service Request | D24: Sasolburg Home Affairs | E24: Anna Mokoena | F24: 109000000000 | G24: 37081 | H24: Male | I24: 075 130 0936 | J24: Ward 17 | L24: Under Review | M24: captured | N24: Q118 | O24: Refilwe Mahlangu | Q24: Applicant did not bring required supporting documents
A25: DHA-000702 | B25: 46302 | C25: Home Affairs - Passport Application | D25: Sebokeng SASSA Office | E25: Dorah Ndlovu | F25: 6400000000000 | G25: 22/01/1964 | H25: F | I25: 075-917-9518 | J25: Ward 5 | L25: Rejected | M25: Escalated | N25: Q134 | O25: Deon Coetzee | Q25: Follow-up call required to confirm banking details
A26: SASSA-000921 | B26: 27-01-2026 | C26: SASSA Grant Application | D26: Evaton SASSA Office | E26: Nokuthula Mokoena | F26: 6610000000000 | G26: 24457 | H26: Female | I26: 622844578 | J26: Ward 16 | K26: Care Dependency Grant | L26: complete | M26: Pending | N26: Q138 | O26: Deon Meyer | Q26: Follow-up call required to confirm banking details
A27: CLN-000842 | B27: 46063 | C27: Clinic - Chronic Medication Collection | D27: Evaton SASSA Office | E27: Pieter Khumalo | F27: 206000000000 | J27: Ward 21 | L27: complete | M27: Resolved | Q27: Urgent case - fast-tracked per supervisor approval
A28: SASSA-000527 | B28: 46096 | C28: SASSA Grant Application | D28: Vanderbijlpark Home Affairs | E28: Lindiwe Kruger | F28: 6310000000000 | G28: 23348 | H28: female | I28: 735394716 | J28: Ward 9 | K28: Foster Child Grant | L28: Incomplete - Missing Proof of Residence | M28: Closed | O28: Andries Sithole
A29: SASSA-000908 | B29: 23-01-2026 | C29: SASSA Grant Application | D29: Emfuleni Municipal Office | E29: Kagiso Fourie | F29: 9310000000000 | G29: 34122 | H29: M | J29: Ward 3 | K29: Care Dependency Grant | L29: Under Review | M29: Captured | N29: Q232 | O29: Deon Swart | Q29: Incorrect ID number provided initially, corrected
A30: DHA-000471 | B30: 46154 | C30: Home Affairs - Birth Certificate | D30: Sasolburg Home Affairs | E30: Thabo Fourie | F30: 512000000000 | G30: 38689 | H30: male | I30: 069-607-0278 | J30: Ward 15 | L30: Complete | O30: Deon Mahlangu | Q30: System offline - captured manually, will upload later
A31: DHA-001022 | B31: 46105 | C31: Home Affairs - Passport Application | D31: Emfuleni Municipal Office | E31: Bongani Mahlangu | F31: 512000000000 | G31: 26-12-2005 | H31: female | I31: 062-860-3174 | J31: Ward 12 | L31: Awaiting Home Affairs Confirmation | M31: CAPTURED | N31: Q045 | O31: Werner Khumalo | P31: 46177 | Q31: Applicant did not bring required supporting documents
A32: DHA000830 | B32: 46189 | C32: Home Affairs - Birth Certificate | D32: Vereeniging Home Affairs | E32: Pieter Kruger | F32: 5810000000000 | G32: 27-07-1958 | H32: Female | I32: 27709426834 | J32: Ward 1 | L32: Pending Verification | M32: Closed | N32: Q265 | O32: Deon Meyer | P32: 46202 | Q32: Home Affairs system down for maintenance during visit
A33: DHA-000793 | B33: 46065 | C33: Home Affairs - Birth Certificate | D33: Evaton SASSA Office | E33: Kagiso Fourie | F33: 6410000000000 | G33: 23637 | H33: M | J33: Ward 14 | L33: Under Review | M33: CAPTURED | N33: Q119 | O33: Palesa Sithole
A34: cln-000444 | B34: 46242 | C34: Clinic - General Consultation | D34: Evaton SASSA Office | E34: Johannes Molefe | F34: 9410000000000 | G34: 34516 | H34: Male | I34: 075 990 8000 | J34: Ward 10 | L34: Pending Verification | M34: Re-opened | N34: Q271 | O34: Refilwe Swart | P34: 13-08-2026 | Q34: Duplicate application found on system - flagged
A35: MUN-000457 | B35: 46182 | C35: Municipal - Service Request | D35: Evaton SASSA Office | E35: Elizabeth Fourie | F35: 806000000000 | G35: 39615 | H35: male | I35: 073 705 2676 | J35: Ward 8 | L35: Awaiting Home Affairs Confirmation | M35: CAPTURED | N35: Q027 | O35: Zanele Khumalo | P35: 46293 | Q35: Applicant is a minor, guardian present and documented
A36: SASSA-000886 | B36: 46261 | C36: SASSA Grant Application | D36: Three Rivers Clinic | E36: Zodwa Kruger | F36: 8910000000000 | G36: 30/10/1989 | I36: 067-412-1980 | K36: Social Relief of Distress (SRD) | L36: Incomplete - Missing Proof of Residence | M36: Captured | N36: Q026 | O36: Refilwe Swart | P36: 19-09-2026 | Q36: Applicant did not bring required supporting documents
A37: DHA-000996 | B37: 13-07-2026 | C37: Home Affairs - Passport Application | D37: Evaton SASSA Office | E37: Elizabeth Fourie | F37: 8610000000000 | G37: 13-07-1986 | H37: F | I37: (062) 4562402 | J37: Ward 21 | K37: Foster Child Grant | L37: Approved | M37: Captured | N37: Q124 | O37: Zanele Sithole
A38: DHA-000464 | B38: 46204 | C38: Home Affairs - ID Application | D38: Sasolburg Home Affairs | E38: Willem Mahlangu | F38: 6410000000000 | G38: 23710 | H38: female | I38: 063 880 3633 | J38: Ward 7 | L38: Approved | M38: captured | O38: Busisiwe Coetzee | Q38: Record incomplete - contact number illegible on form
A39: sassa-000991 | B39: 46136 | C39: SASSA Grant Application | D39: Vanderbijlpark Home Affairs | E39: Bongani Fourie | F39: 6041856770 | G39: 18-04-2006 | H39: M | I39: 661962007 | J39: Ward 9 | K39: Older Person's Grant | L39: Pending Verification | M39: CAPTURED | N39: Q144 | O39: Palesa Radebe | P39: 46149 | Q39: Biometric capture failed, rescheduled
A40: MUN000012 | B40: 46151 | C40: Municipal - Account Query | D40: Sebokeng SASSA Office | E40: Marie Dlamini | F40: 7000000000000 | G40: 15/04/1970 | H40: female | I40: 071-688-8859 | J40: Ward 10 | N40: Q033
...

Sheet Cleaned Data
A1: =citizen_services_records_log!A1 -> Case Reference | B1: =citizen_services_records_log!B1 -> Date Captured | C1: =citizen_services_records_log!C1 -> Service Type | D1: =citizen_services_records_log!D1 -> Branch/Office | E1: =citizen_services_records_log!E1 -> Applicant Full Name | F1: =citizen_services_records_log!F1 -> ID Number | G1: =citizen_services_records_log!G1 -> Date of Birth | H1: =citizen_services_records_log!H1 -> Gender | ... Q1: =citizen_services_records_log!Q1 -> Notes
A2: =IF(ISBLANK(citizen_services_records_log!A2),"None",(CONCATENATE(UPPER(_xlfn.TEXTBEFORE(SUBSTITUTE(citizen_services_records_log!A2, "-", ""), {"0","1","2","3","4","5","6","7","8","9"}, 1)),"-",RIGHT(citizen_services_records_log!A2,6)))) -> SASSA-000796 | B2: =IF(ISBLANK(citizen_services_records_log!B2),"None",IF(ISNUMBER(citizen_services_records_log!B2),citizen_services_records_log!B2,DATE(RIGHT(citizen_services_records_log!B2,4),MID(citizen_services_records_log!B2,4,2),LEFT(citizen_services_records_log!B2,2)))) -> 46156 | C2: =IF(citizen_services_records_log!C2 = "SASSA Grant Status Enquiry","SASSA - Grant Status Enquiry",IF(citizen_services_records_log!C2 = "SASSA Grant Application", "SASSA - Grant Application", IF(citizen_services_records_log!C2=0,"None", citizen_services_records_log!C2))) -> SASSA - Grant Application | D2: {=_xlfn.IFS(ISTEXT(citizen_services_records_log!D2),PROPER(citizen_services_records_log!D2),ISBLANK(citizen_services_records_log!D2),"None")} -> Sharpeville Clinic | E2: {=_xlfn.IFS(ISTEXT(citizen_services_records_log!E2),PROPER(citizen_services_records_log!E2),ISBLANK(citizen_services_records_log!E2),"None")} -> Nomvula Fourie | F2: {=_xlfn.IFS(ISBLANK(citizen_services_records_log!F2),"None", TYPE(citizen_services_records_log!F2)=1,citizen_services_records_log!F2,citizen_services_records_log!F2="ID NOT PROVIDED","ID not provided" )} -> 8500000000000 | G2: =IF(ISBLANK(citizen_services_records_log!G2),"None",IF(ISNUMBER(citizen_services_records_log!G2),citizen_services_records_log!G2,DATE(RIGHT(citizen_services_records_log!G2,4),MID(citizen_services_records_log!G2,4,2),LEFT(citizen_services_records_log!G2,2)))) -> 31160 | H2: {=_xlfn.IFS(citizen_services_records_log!H2="M", "Male", citizen_services_records_log!H2 = "F", "Female", citizen_services_records_log!H2="male", "Male", citizen_services_records_log!H2="female","Female", ISBLANK(citizen_services_records_log!H2),"None", citizen_services_records_log!H2 = "Female", "Female", citizen_services_records_log!H2="Male","Male")} -> Male | I2: =IF(OR(ISBLANK(citizen_services_records_log!I2),UPPER(TRIM(citizen_services_records_log!I2))="N/A"),"None",_xlfn.LET(_xlpm.d,RIGHT(SUBSTITUTE(SUBSTITUTE(SUBSTITUTE(SUBSTITUTE(citizen_services_records_log!I2," ",""),"-",""),"(",""),")",""),9),"0"&LEFT(_xlpm.d,2)&" "&MID(_xlpm.d,3,3)&" "&RIGHT(_xlpm.d,4))) -> 072 291 3562 | J2: {=_xlfn.IFS(ISTEXT(citizen_services_records_log!J2),citizen_services_records_log!J2,ISBLANK(citizen_services_records_log!J2),"None")} -> Ward 20 | K2: {=_xlfn.IFS(ISTEXT(citizen_services_records_log!K2),citizen_services_records_log!K2, ISBLANK(citizen_services_records_log!K2),"None")} -> Older Person's Grant | L2: {=SUBSTITUTE(PROPER(_xlfn.IFS(ISTEXT(citizen_services_records_log!L2),citizen_services_records_log!L2, ISBLANK(citizen_services_records_log!L2),"None")),"Id","ID",1)} -> Pending Verification | M2: {=IF(citizen_services_records_log!M2 = "Re-opened","Re-opened",PROPER(_xlfn.IFS(ISTEXT(citizen_services_records_log!M2),citizen_services_records_log!M2, ISBLANK(citizen_services_records_log!M2),"None")))} -> Resolved | N2: {=(_xlfn.IFS(ISTEXT(citizen_services_records_log!N2),citizen_services_records_log!N2,ISBLANK(citizen_services_records_log!N2),"None"))} -> Q137 | O2: {=_xlfn.IFS(ISTEXT(citizen_services_records_log!O2),PROPER(citizen_services_records_log!O2),ISBLANK(citizen_services_records_log!O2),"None")} -> Werner Meyer | P2: =IF(ISBLANK(citizen_services_records_log!P2),"None",IF(ISNUMBER(citizen_services_records_log!P2),citizen_services_records_log!P2,DATE(RIGHT(citizen_services_records_log!P2,4),MID(citizen_services_records_log!P2,4,2),LEFT(citizen_services_records_log!P2,2)))) -> 46175 | Q2: {=SUBSTITUTE(_xlfn.IFS(ISTEXT(citizen_services_records_log!Q2),PROPER(citizen_services_records_log!Q2),ISBLANK(citizen_services_records_log!Q2),"None"),"Id","ID",1)} -> System Offline - Captured Manually, Will Upload Later
A3: =IF(ISBLANK(citizen_services_records_log!A3),"None",(CONCATENATE(UPPER(_xlfn.TEXTBEFORE(SUBSTITUTE(citizen_services_records_log!A3, "-", ""), {"0","1","2","3","4","5","6","7","8","9"}, 1)),"-",RIGHT(citizen_services_records_log!A3,6)))) -> DHA-001034 | B3: =IF(ISBLANK(citizen_services_records_log!B3),"None",IF(ISNUMBER(citizen_services_records_log!B3),citizen_services_records_log!B3,DATE(RIGHT(citizen_services_records_log!B3,4),MID(citizen_services_records_log!B3,4,2),LEFT(citizen_services_records_log!B3,2)))) -> 46127 | C3: =IF(citizen_services_records_log!C3 = "SASSA Grant Status Enquiry","SASSA - Grant Status Enquiry",IF(citizen_services_records_log!C3 = "SASSA Grant Application", "SASSA - Grant Application", IF(citizen_services_records_log!C3=0,"None", citizen_services_records_log!C3))) -> Home Affairs - Passport Application | D3: {=_xlfn.IFS(ISTEXT(citizen_services_records_log!D3),PROPER(citizen_services_records_log!D3),ISBLANK(citizen_services_records_log!D3),"None")} -> Vanderbijlpark Home Affairs | E3: {=_xlfn.IFS(ISTEXT(citizen_services_records_log!E3),PROPER(citizen_services_records_log!E3),ISBLANK(citizen_services_records_log!E3),"None")} -> Marie Van Der Merwe | F3: {=_xlfn.IFS(ISBLANK(citizen_services_records_log!F3),"None", TYPE(citizen_services_records_log!F3)=1,citizen_services_records_log!F3,citizen_services_records_log!F3="ID NOT PROVIDED","ID not provided" )} -> 7910000000000 | G3: =IF(ISBLANK(citizen_services_records_log!G3),"None",IF(ISNUMBER(citizen_services_records_log!G3),citizen_services_records_log!G3,DATE(RIGHT(citizen_services_records_log!G3,4),MID(citizen_services_records_log!G3,4,2),LEFT(citizen_services_records_log!G3,2)))) -> 29118 | H3: {=_xlfn.IFS(citizen_services_records_log!H3="M", "Male", citizen_services_records_log!H3 = "F", "Female", citizen_services_records_log!H3="male", "Male", citizen_services_records_log!H3="female","Female", ISBLANK(citizen_services_records_log!H3),"None", citizen_services_records_log!H3 = "Female", "Female", citizen_services_records_log!H3="Male","Male")} -> Male | I3: =IF(OR(ISBLANK(citizen_services_records_log!I3),UPPER(TRIM(citizen_services_records_log!I3))="N/A"),"None",_xlfn.LET(_xlpm.d,RIGHT(SUBSTITUTE(SUBSTITUTE(SUBSTITUTE(SUBSTITUTE(citizen_services_records_log!I3," ",""),"-",""),"(",""),")",""),9),"0"&LEFT(_xlpm.d,2)&" "&MID(_xlpm.d,3,3)&" "&RIGHT(_xlpm.d,4))) -> 067 773 4000 | J3: {=_xlfn.IFS(ISTEXT(citizen_services_records_log!J3),citizen_services_records_log!J3,ISBLANK(citizen_services_records_log!J3),"None")} -> Ward 18 | K3: {=_xlfn.IFS(ISTEXT(citizen_services_records_log!K3),citizen_services_records_log!K3, ISBLANK(citizen_services_records_log!K3),"None")} -> None | L3: {=SUBSTITUTE(PROPER(_xlfn.IFS(ISTEXT(citizen_services_records_log!L3),citizen_services_records_log!L3, ISBLANK(citizen_services_records_log!L3),"None")),"Id","ID",1)} -> Under Review | M3: {=IF(citizen_services_records_log!M3 = "Re-opened","Re-opened",PROPER(_xlfn.IFS(ISTEXT(citizen_services_records_log!M3),citizen_services_records_log!M3, ISBLANK(citizen_services_records_log!M3),"None")))} -> Captured | N3: {=(_xlfn.IFS(ISTEXT(citizen_services_records_log!N3),citizen_services_records_log!N3,ISBLANK(citizen_services_records_log!N3),"None"))} -> Q008 | O3: {=_xlfn.IFS(ISTEXT(citizen_services_records_log!O3),PROPER(citizen_services_records_log!O3),ISBLANK(citizen_services_records_log!O3),"None")} -> Lerato Mahlangu | P3: =IF(ISBLANK(citizen_services_records_log!P3),"None",IF(ISNUMBER(citizen_services_records_log!P3),citizen_services_records_log!P3,DATE(RIGHT(citizen_services_records_log!P3,4),MID(citizen_services_records_log!P3,4,2),LEFT(citizen_services_records_log!P3,2)))) -> None | Q3: {=SUBSTITUTE(_xlfn.IFS(ISTEXT(citizen_services_records_log!Q3),PROPER(citizen_services_records_log!Q3),ISBLANK(citizen_services_records_log!Q3),"None"),"Id","ID",1)} -> Grant Payment Query - Referred To Sassa Call Centre
A4: =IF(ISBLANK(citizen_services_records_log!A4),"None",(CONCATENATE(UPPER(_xlfn.TEXTBEFORE(SUBSTITUTE(citizen_services_records_log!A4, "-", ""), {"0","1","2","3","4","5","6","7","8","9"}, 1)),"-",RIGHT(citizen_services_records_log!A4,6)))) -> MUN-000761 | B4: =IF(ISBLANK(citizen_services_records_log!B4),"None",IF(ISNUMBER(citizen_services_records_log!B4),citizen_services_records_log!B4,DATE(RIGHT(citizen_services_records_log!B4,4),MID(citizen_services_records_log!B4,4,2),LEFT(citizen_services_records_log!B4,2)))) -> 46281 | C4: =IF(citizen_services_records_log!C4 = "SASSA Grant Status Enquiry","SASSA - Grant Status Enquiry",IF(citizen_services_records_log!C4 = "SASSA Grant Application", "SASSA - Grant Application", IF(citizen_services_records_log!C4=0,"None", citizen_services_records_log!C4))) -> Municipal - Service Request | D4: {=_xlfn.IFS(ISTEXT(citizen_services_records_log!D4),PROPER(citizen_services_records_log!D4),ISBLANK(citizen_services_records_log!D4),"None")} -> Vanderbijlpark Home Affairs | E4: {=_xlfn.IFS(ISTEXT(citizen_services_records_log!E4),PROPER(citizen_services_records_log!E4),ISBLANK(citizen_services_records_log!E4),"None")} -> Nomvula Pretorius | F4: {=_xlfn.IFS(ISBLANK(citizen_services_records_log!F4),"None", TYPE(citizen_services_records_log!F4)=1,citizen_services_records_log!F4,citizen_services_records_log!F4="ID NOT PROVIDED","ID not provided" )} -> None | G4: =IF(ISBLANK(citizen_services_records_log!G4),"None",IF(ISNUMBER(citizen_services_records_log!G4),citizen_services_records_log!G4,DATE(RIGHT(citizen_services_records_log!G4,4),MID(citizen_services_records_log!G4,4,2),LEFT(citizen_services_records_log!G4,2)))) -> 30487 | H4: {=_xlfn.IFS(citizen_services_records_log!H4="M", "Male", citizen_services_records_log!H4 = "F", "Female", citizen_services_records_log!H4="male", "Male", citizen_services_records_log!H4="female","Female", ISBLANK(citizen_services_records_log!H4),"None", citizen_services_records_log!H4 = "Female", "Female", citizen_services_records_log!H4="Male","Male")} -> Female | I4: =IF(OR(ISBLANK(citizen_services_records_log!I4),UPPER(TRIM(citizen_services_records_log!I4))="N/A"),"None",_xlfn.LET(_xlpm.d,RIGHT(SUBSTITUTE(SUBSTITUTE(SUBSTITUTE(SUBSTITUTE(citizen_services_records_log!I4," ",""),"-",""),"(",""),")",""),9),"0"&LEFT(_xlpm.d,2)&" "&MID(_xlpm.d,3,3)&" "&RIGHT(_xlpm.d,4))) -> 081 175 7562 | J4: {=_xlfn.IFS(ISTEXT(citizen_services_records_log!J4),citizen_services_records_log!J4,ISBLANK(citizen_services_records_log!J4),"None")} -> Ward 7 | K4: {=_xlfn.IFS(ISTEXT(citizen_services_records_log!K4),citizen_services_records_log!K4, ISBLANK(citizen_services_records_log!K4),"None")} -> None | L4: {=SUBSTITUTE(PROPER(_xlfn.IFS(ISTEXT(citizen_services_records_log!L4),citizen_services_records_log!L4, ISBLANK(citizen_services_records_log!L4),"None")),"Id","ID",1)} -> None | M4: {=IF(citizen_services_records_log!M4 = "Re-opened","Re-opened",PROPER(_xlfn.IFS(ISTEXT(citizen_services_records_log!M4),citizen_services_records_log!M4, ISBLANK(citizen_services_records_log!M4),"None")))} -> Closed | N4: {=(_xlfn.IFS(ISTEXT(citizen_services_records_log!N4),citizen_services_records_log!N4,ISBLANK(citizen_services_records_log!N4),"None"))} -> Q055 | O4: {=_xlfn.IFS(ISTEXT(citizen_services_records_log!O4),PROPER(citizen_services_records_log!O4),ISBLANK(citizen_services_records_log!O4),"None")} -> Refilwe Khumalo | P4: =IF(ISBLANK(citizen_services_records_log!P4),"None",IF(ISNUMBER(citizen_services_records_log!P4),citizen_services_records_log!P4,DATE(RIGHT(citizen_services_records_log!P4,4),MID(citizen_services_records_log!P4,4,2),LEFT(citizen_services_records_log!P4,2)))) -> None | Q4: {=SUBSTITUTE(_xlfn.IFS(ISTEXT(citizen_services_records_log!Q4),PROPER(citizen_services_records_log!Q4),ISBLANK(citizen_services_records_log!Q4),"None"),"Id","ID",1)} -> None
A5: =IF(ISBLANK(citizen_services_records_log!A5),"None",(CONCATENATE(UPPER(_xlfn.TEXTBEFORE(SUBSTITUTE(citizen_services_records_log!A5, "-", ""), {"0","1","2","3","4","5","6","7","8","9"}, 1)),"-",RIGHT(citizen_services_records_log!A5,6)))) -> DHA-000959 | B5: =IF(ISBLANK(citizen_services_records_log!B5),"None",IF(ISNUMBER(citizen_services_records_log!B5),citizen_services_records_log!B5,DATE(RIGHT(citizen_services_records_log!B5,4),MID(citizen_services_records_log!B5,4,2),LEFT(citizen_services_records_log!B5,2)))) -> 46234 | C5: =IF(citizen_services_records_log!C5 = "SASSA Grant Status Enquiry","SASSA - Grant Status Enquiry",IF(citizen_services_records_log!C5 = "SASSA Grant Application", "SASSA - Grant Application", IF(citizen_services_records_log!C5=0,"None", citizen_services_records_log!C5))) -> Home Affairs - Birth Certificate | D5: {=_xlfn.IFS(ISTEXT(citizen_services_records_log!D5),PROPER(citizen_services_records_log!D5),ISBLANK(citizen_services_records_log!D5),"None")} -> Emfuleni Municipal Office | E5: {=_xlfn.IFS(ISTEXT(citizen_services_records_log!E5),PROPER(citizen_services_records_log!E5),ISBLANK(citizen_services_records_log!E5),"None")} -> Marie Mokgadi | F5: {=_xlfn.IFS(ISBLANK(citizen_services_records_log!F5),"None", TYPE(citizen_services_records_log!F5)=1,citizen_services_records_log!F5,citizen_services_records_log!F5="ID NOT PROVIDED","ID not provided" )} -> None | G5: =IF(ISBLANK(citizen_services_records_log!G5),"None",IF(ISNUMBER(citizen_services_records_log!G5),citizen_services_records_log!G5,DATE(RIGHT(citizen_services_records_log!G5,4),MID(citizen_services_records_log!G5,4,2),LEFT(citizen_services_records_log!G5,2)))) -> None | H5: {=_xlfn.IFS(citizen_services_records_log!H5="M", "Male", citizen_services_records_log!H5 = "F", "Female", citizen_services_records_log!H5="male", "Male", citizen_services_records_log!H5="female","Female", ISBLANK(citizen_services_records_log!H5),"None", citizen_services_records_log!H5 = "Female", "Female", citizen_services_records_log!H5="Male","Male")} -> Male | I5: =IF(OR(ISBLANK(citizen_services_records_log!I5),UPPER(TRIM(citizen_services_records_log!I5))="N/A"),"None",_xlfn.LET(_xlpm.d,RIGHT(SUBSTITUTE(SUBSTITUTE(SUBSTITUTE(SUBSTITUTE(citizen_services_records_log!I5," ",""),"-",""),"(",""),")",""),9),"0"&LEFT(_xlpm.d,2)&" "&MID(_xlpm.d,3,3)&" "&RIGHT(_xlpm.d,4))) -> 075 123 0616 | J5: {=_xlfn.IFS(ISTEXT(citizen_services_records_log!J5),citizen_services_records_log!J5,ISBLANK(citizen_services_records_log!J5),"None")} -> Ward 6 | K5: {=_xlfn.IFS(ISTEXT(citizen_services_records_log!K5),citizen_services_records_log!K5, ISBLANK(citizen_services_records_log!K5),"None")} -> None | L5: {=SUBSTITUTE(PROPER(_xlfn.IFS(ISTEXT(citizen_services_records_log!L5),citizen_services_records_log!L5, ISBLANK(citizen_services_records_log!L5),"None")),"Id","ID",1)} -> Complete | M5: {=IF(citizen_services_records_log!M5 = "Re-opened","Re-opened",PROPER(_xlfn.IFS(ISTEXT(citizen_services_records_log!M5),citizen_services_records_log!M5, ISBLANK(citizen_services_records_log!M5),"None")))} -> Awaiting Documents | N5: {=(_xlfn.IFS(ISTEXT(citizen_services_records_log!N5),citizen_services_records_log!N5,ISBLANK(citizen_services_records_log!N5),"None"))} -> Q244 | O5: {=_xlfn.IFS(ISTEXT(citizen_services_records_log!O5),PROPER(citizen_services_records_log!O5),ISBLANK(citizen_services_records_log!O5),"None")} -> Refilwe Nel | P5: =IF(ISBLANK(citizen_services_records_log!P5),"None",IF(ISNUMBER(citizen_services_records_log!P5),citizen_services_records_log!P5,DATE(RIGHT(citizen_services_records_log!P5,4),MID(citizen_services_records_log!P5,4,2),LEFT(citizen_services_records_log!P5,2)))) -> None | Q5: {=SUBSTITUTE(_xlfn.IFS(ISTEXT(citizen_services_records_log!Q5),PROPER(citizen_services_records_log!Q5),ISBLANK(citizen_services_records_log!Q5),"None"),"Id","ID",1)} -> None
A6: =IF(ISBLANK(citizen_services_records_log!A6),"None",(CONCATENATE(UPPER(_xlfn.TEXTBEFORE(SUBSTITUTE(citizen_services_records_log!A6, "-", ""), {"0","1","2","3","4","5","6","7","8","9"}, 1)),"-",RIGHT(citizen_services_records_log!A6,6)))) -> SASSA-000603 | B6: =IF(ISBLANK(citizen_services_records_log!B6),"None",IF(ISNUMBER(citizen_services_records_log!B6),citizen_services_records_log!B6,DATE(RIGHT(citizen_services_records_log!B6,4),MID(citizen_services_records_log!B6,4,2),LEFT(citizen_services_records_log!B6,2)))) -> 46093 | C6: =IF(citizen_services_records_log!C6 = "SASSA Grant Status Enquiry","SASSA - Grant Status Enquiry",IF(citizen_services_records_log!C6 = "SASSA Grant Application", "SASSA - Grant Application", IF(citizen_services_records_log!C6=0,"None", citizen_services_records_log!C6))) -> SASSA - Grant Application | D6: {=_xlfn.IFS(ISTEXT(citizen_services_records_log!D6),PROPER(citizen_services_records_log!D6),ISBLANK(citizen_services_records_log!D6),"None")} -> Emfuleni Municipal Office | E6: {=_xlfn.IFS(ISTEXT(citizen_services_records_log!E6),PROPER(citizen_services_records_log!E6),ISBLANK(citizen_services_records_log!E6),"None")} -> Grace Steyn | F6: {=_xlfn.IFS(ISBLANK(citizen_services_records_log!F6),"None", TYPE(citizen_services_records_log!F6)=1,citizen_services_records_log!F6,citizen_services_records_log!F6="ID NOT PROVIDED","ID not provided" )} -> None | G6: =IF(ISBLANK(citizen_services_records_log!G6),"None",IF(ISNUMBER(citizen_services_records_log!G6),citizen_services_records_log!G6,DATE(RIGHT(citizen_services_records_log!G6,4),MID(citizen_services_records_log!G6,4,2),LEFT(citizen_services_records_log!G6,2)))) -> 16512 | H6: {=_xlfn.IFS(citizen_services_records_log!H6="M", "Male", citizen_services_records_log!H6 = "F", "Female", citizen_services_records_log!H6="male", "Male", citizen_services_records_log!H6="female","Female", ISBLANK(citizen_services_records_log!H6),"None", citizen_services_records_log!H6 = "Female", "Female", citizen_services_records_log!H6="Male","Male")} -> Male | I6: =IF(OR(ISBLANK(citizen_services_records_log!I6),UPPER(TRIM(citizen_services_records_log!I6))="N/A"),"None",_xlfn.LET(_xlpm.d,RIGHT(SUBSTITUTE(SUBSTITUTE(SUBSTITUTE(SUBSTITUTE(citizen_services_records_log!I6," ",""),"-",""),"(",""),")",""),9),"0"&LEFT(_xlpm.d,2)&" "&MID(_xlpm.d,3,3)&" "&RIGHT(_xlpm.d,4))) -> 076 711 8567 | J6: {=_xlfn.IFS(ISTEXT(citizen_services_records_log!J6),citizen_services_records_log!J6,ISBLANK(citizen_services_records_log!J6),"None")} -> Ward 20 | K6: {=_xlfn.IFS(ISTEXT(citizen_services_records_log!K6),citizen_services_records_log!K6, ISBLANK(citizen_services_records_log!K6),"None")} -> Social Relief of Distress (SRD) | L6: {=SUBSTITUTE(PROPER(_xlfn.IFS(ISTEXT(citizen_services_records_log!L6),citizen_services_records_log!L6, ISBLANK(citizen_services_records_log!L6),"None")),"Id","ID",1)} -> None | M6: {=IF(citizen_services_records_log!M6 = "Re-opened","Re-opened",PROPER(_xlfn.IFS(ISTEXT(citizen_services_records_log!M6),citizen_services_records_log!M6, ISBLANK(citizen_services_records_log!M6),"None")))} -> Escalated | N6: {=(_xlfn.IFS(ISTEXT(citizen_services_records_log!N6),citizen_services_records_log!N6,ISBLANK(citizen_services_records_log!N6),"None"))} -> Q211 | O6: {=_xlfn.IFS(ISTEXT(citizen_services_records_log!O6),PROPER(citizen_services_records_log!O6),ISBLANK(citizen_services_records_log!O6),"None")} -> Lerato Nel | P6: =IF(ISBLANK(citizen_services_records_log!P6),"None",IF(ISNUMBER(citizen_services_records_log!P6),citizen_services_records_log!P6,DATE(RIGHT(citizen_services_records_log!P6,4),MID(citizen_services_records_log!P6,4,2),LEFT(citizen_services_records_log!P6,2)))) -> None | Q6: {=SUBSTITUTE(_xlfn.IFS(ISTEXT(citizen_services_records_log!Q6),PROPER(citizen_services_records_log!Q6),ISBLANK(citizen_services_records_log!Q6),"None"),"Id","ID",1)} -> Urgent Case - Fast-Tracked Per Supervisor Approval
A7: =IF(ISBLANK(citizen_services_records_log!A7),"None",(CONCATENATE(UPPER(_xlfn.TEXTBEFORE(SUBSTITUTE(citizen_services_records_log!A7, "-", ""), {"0","1","2","3","4","5","6","7","8","9"}, 1)),"-",RIGHT(citizen_services_records_log!A7,6)))) -> CLN-000736 | B7: =IF(ISBLANK(citizen_services_records_log!B7),"None",IF(ISNUMBER(citizen_services_records_log!B7),citizen_services_records_log!B7,DATE(RIGHT(citizen_services_records_log!B7,4),MID(citizen_services_records_log!B7,4,2),LEFT(citizen_services_records_log!B7,2)))) -> 46226 | C7: =IF(citizen_services_records_log!C7 = "SASSA Grant Status Enquiry","SASSA - Grant Status Enquiry",IF(citizen_services_records_log!C7 = "SASSA Grant Application", "SASSA - Grant Application", IF(citizen_services_records_log!C7=0,"None", citizen_services_records_log!C7))) -> Clinic - Chronic Medication Collection | D7: {=_xlfn.IFS(ISTEXT(citizen_services_records_log!D7),PROPER(citizen_services_records_log!D7),ISBLANK(citizen_services_records_log!D7),"None")} -> Vanderbijlpark Home Affairs | E7: {=_xlfn.IFS(ISTEXT(citizen_services_records_log!E7),PROPER(citizen_services_records_log!E7),ISBLANK(citizen_services_records_log!E7),"None")} -> Dorah Mokoena | F7: {=_xlfn.IFS(ISBLANK(citizen_services_records_log!F7),"None", TYPE(citizen_services_records_log!F7)=1,citizen_services_records_log!F7,citizen_services_records_log!F7="ID NOT PROVIDED","ID not provided" )} -> 7110000000000 | G7: =IF(ISBLANK(citizen_services_records_log!G7),"None",IF(ISNUMBER(citizen_services_records_log!G7),citizen_services_records_log!G7,DATE(RIGHT(citizen_services_records_log!G7,4),MID(citizen_services_records_log!G7,4,2),LEFT(citizen_services_records_log!G7,2)))) -> 26004 | H7: {=_xlfn.IFS(citizen_services_records_log!H7="M", "Male", citizen_services_records_log!H7 = "F", "Female", citizen_services_records_log!H7="male", "Male", citizen_services_records_log!H7="female","Female", ISBLANK(citizen_services_records_log!H7),"None", citizen_services_records_log!H7 = "Female", "Female", citizen_services_records_log!H7="Male","Male")} -> Female | I7: =IF(OR(ISBLANK(citizen_services_records_log!I7),UPPER(TRIM(citizen_services_records_log!I7))="N/A"),"None",_xlfn.LET(_xlpm.d,RIGHT(SUBSTITUTE(SUBSTITUTE(SUBSTITUTE(SUBSTITUTE(citizen_services_records_log!I7," ",""),"-",""),"(",""),")",""),9),"0"&LEFT(_xlpm.d,2)&" "&MID(_xlpm.d,3,3)&" "&RIGHT(_xlpm.d,4))) -> 081 839 9641 | J7: {=_xlfn.IFS(ISTEXT(citizen_services_records_log!J7),citizen_services_records_log!J7,ISBLANK(citizen_services_records_log!J7),"None")} -> Ward 23 | K7: {=_xlfn.IFS(ISTEXT(citizen_services_records_log!K7),citizen_services_records_log!K7, ISBLANK(citizen_services_records_log!K7),"None")} -> None | L7: {=SUBSTITUTE(PROPER(_xlfn.IFS(ISTEXT(citizen_services_records_log!L7),citizen_services_records_log!L7, ISBLANK(citizen_services_records_log!L7),"None")),"Id","ID",1)} -> Under Review | M7: {=IF(citizen_services_records_log!M7 = "Re-opened","Re-opened",PROPER(_xlfn.IFS(ISTEXT(citizen_services_records_log!M7),citizen_services_records_log!M7, ISBLANK(citizen_services_records_log!M7),"None")))} -> Resolved | N7: {=(_xlfn.IFS(ISTEXT(citizen_services_records_log!N7),citizen_services_records_log!N7,ISBLANK(citizen_services_records_log!N7),"None"))} -> Q094 | O7: {=_xlfn.IFS(ISTEXT(citizen_services_records_log!O7),PROPER(citizen_services_records_log!O7),ISBLANK(citizen_services_records_log!O7),"None")} -> Andries Meyer | P7: =IF(ISBLANK(citizen_services_records_log!P7),"None",IF(ISNUMBER(citizen_services_records_log!P7),citizen_services_records_log!P7,DATE(RIGHT(citizen_services_records_log!P7,4),MID(citizen_services_records_log!P7,4,2),LEFT(citizen_services_records_log!P7,2)))) -> None | Q7: {=SUBSTITUTE(_xlfn.IFS(ISTEXT(citizen_services_records_log!Q7),PROPER(citizen_services_records_log!Q7),ISBLANK(citizen_services_records_log!Q7),"None"),"Id","ID",1)} -> Applicant Is A Minor, Guardian Present And Documented
A8: =IF(ISBLANK(citizen_services_records_log!A8),"None",(CONCATENATE(UPPER(_xlfn.TEXTBEFORE(SUBSTITUTE(citizen_services_records_log!A8, "-", ""), {"0","1","2","3","4","5","6","7","8","9"}, 1)),"-",RIGHT(citizen_services_records_log!A8,6)))) -> MUN-000968 | B8: =IF(ISBLANK(citizen_services_records_log!B8),"None",IF(ISNUMBER(citizen_services_records_log!B8),citizen_services_records_log!B8,DATE(RIGHT(citizen_services_records_log!B8,4),MID(citizen_services_records_log!B8,4,2),LEFT(citizen_services_records_log!B8,2)))) -> 46198 | C8: =IF(citizen_services_records_log!C8 = "SASSA Grant Status Enquiry","SASSA - Grant Status Enquiry",IF(citizen_services_records_log!C8 = "SASSA Grant Application", "SASSA - Grant Application", IF(citizen_services_records_log!C8=0,"None", citizen_services_records_log!C8))) -> Municipal - Account Query | D8: {=_xlfn.IFS(ISTEXT(citizen_services_records_log!D8),PROPER(citizen_services_records_log!D8),ISBLANK(citizen_services_records_log!D8),"None")} -> Vereeniging Home Affairs | E8: {=_xlfn.IFS(ISTEXT(citizen_services_records_log!E8),PROPER(citizen_services_records_log!E8),ISBLANK(citizen_services_records_log!E8),"None")} -> Sipho Mokgadi | F8: {=_xlfn.IFS(ISBLANK(citizen_services_records_log!F8),"None", TYPE(citizen_services_records_log!F8)=1,citizen_services_records_log!F8,citizen_services_records_log!F8="ID NOT PROVIDED","ID not provided" )} -> 207000000000 | G8: =IF(ISBLANK(citizen_services_records_log!G8),"None",IF(ISNUMBER(citizen_services_records_log!G8),citizen_services_records_log!G8,DATE(RIGHT(citizen_services_records_log!G8,4),MID(citizen_services_records_log!G8,4,2),LEFT(citizen_services_records_log!G8,2)))) -> 37454 | H8: {=_xlfn.IFS(citizen_services_records_log!H8="M", "Male", citizen_services_records_log!H8 = "F", "Female", citizen_services_records_log!H8="male", "Male", citizen_services_records_log!H8="female","Female", ISBLANK(citizen_services_records_log!H8),"None", citizen_services_records_log!H8 = "Female", "Female", citizen_services_records_log!H8="Male","Male")} -> Female | I8: =IF(OR(ISBLANK(citizen_services_records_log!I8),UPPER(TRIM(citizen_services_records_log!I8))="N/A"),"None",_xlfn.LET(_xlpm.d,RIGHT(SUBSTITUTE(SUBSTITUTE(SUBSTITUTE(SUBSTITUTE(citizen_services_records_log!I8," ",""),"-",""),"(",""),")",""),9),"0"&LEFT(_xlpm.d,2)&" "&MID(_xlpm.d,3,3)&" "&RIGHT(_xlpm.d,4))) -> 073 333 3031 | J8: {=_xlfn.IFS(ISTEXT(citizen_services_records_log!J8),citizen_services_records_log!J8,ISBLANK(citizen_services_records_log!J8),"None")} -> Ward 11 | K8: {=_xlfn.IFS(ISTEXT(citizen_services_records_log!K8),citizen_services_records_log!K8, ISBLANK(citizen_services_records_log!K8),"None")} -> None | L8: {=SUBSTITUTE(PROPER(_xlfn.IFS(ISTEXT(citizen_services_records_log!L8),citizen_services_records_log!L8, ISBLANK(citizen_services_records_log!L8),"None")),"Id","ID",1)} -> Complete | M8: {=IF(citizen_services_records_log!M8 = "Re-opened","Re-opened",PROPER(_xlfn.IFS(ISTEXT(citizen_services_records_log!M8),citizen_services_records_log!M8, ISBLANK(citizen_services_records_log!M8),"None")))} -> Captured | N8: {=(_xlfn.IFS(ISTEXT(citizen_services_records_log!N8),citizen_services_records_log!N8,ISBLANK(citizen_services_records_log!N8),"None"))} -> Q186 | O8: {=_xlfn.IFS(ISTEXT(citizen_services_records_log!O8),PROPER(citizen_services_records_log!O8),ISBLANK(citizen_services_records_log!O8),"None")} -> Andries Mahlangu | P8: =IF(ISBLANK(citizen_services_records_log!P8),"None",IF(ISNUMBER(citizen_services_records_log!P8),citizen_services_records_log!P8,DATE(RIGHT(citizen_services_records_log!P8,4),MID(citizen_services_records_log!P8,4,2),LEFT(citizen_services_records_log!P8,2)))) -> None | Q8: {=SUBSTITUTE(_xlfn.IFS(ISTEXT(citizen_services_records_log!Q8),PROPER(citizen_services_records_log!Q8),ISBLANK(citizen_services_records_log!Q8),"None"),"Id","ID",1)} -> Home Affairs System Down For Maintenance During Visit
A9: =IF(ISBLANK(citizen_services_records_log!A9),"None",(CONCATENATE(UPPER(_xlfn.TEXTBEFORE(SUBSTITUTE(citizen_services_records_log!A9, "-", ""), {"0","1","2","3","4","5","6","7","8","9"}, 1)),"-",RIGHT(citizen_services_records_log!A9,6)))) -> MUN-000202 | B9: =IF(ISBLANK(citizen_services_records_log!B9),"None",IF(ISNUMBER(citizen_services_records_log!B9),citizen_services_records_log!B9,DATE(RIGHT(citizen_services_records_log!B9,4),MID(citizen_services_records_log!B9,4,2),LEFT(citizen_services_records_log!B9,2)))) -> 46297 | C9: =IF(citizen_services_records_log!C9 = "SASSA Grant Status Enquiry","SASSA - Grant Status Enquiry",IF(citizen_services_records_log!C9 = "SASSA Grant Application", "SASSA - Grant Application", IF(citizen_services_records_log!C9=0,"None", citizen_services_records_log!C9))) -> Municipal - Account Query | D9: {=_xlfn.IFS(ISTEXT(citizen_services_records_log!D9),PROPER(citizen_services_records_log!D9),ISBLANK(citizen_services_records_log!D9),"None")} -> Meyerton Municipal Office | E9: {=_xlfn.IFS(ISTEXT(citizen_services_records_log!E9),PROPER(citizen_services_records_log!E9),ISBLANK(citizen_services_records_log!E9),"None")} -> Tumelo Ndlovu | F9: {=_xlfn.IFS(ISBLANK(citizen_services_records_log!F9),"None", TYPE(citizen_services_records_log!F9)=1,citizen_services_records_log!F9,citizen_services_records_log!F9="ID NOT PROVIDED","ID not provided" )} -> 203000000000 | G9: =IF(ISBLANK(citizen_services_records_log!G9),"None",IF(ISNUMBER(citizen_services_records_log!G9),citizen_services_records_log!G9,DATE(RIGHT(citizen_services_records_log!G9,4),MID(citizen_services_records_log!G9,4,2),LEFT(citizen_services_records_log!G9,2)))) -> 37343 | H9: {=_xlfn.IFS(citizen_services_records_log!H9="M", "Male", citizen_services_records_log!H9 = "F", "Female", citizen_services_records_log!H9="male", "Male", citizen_services_records_log!H9="female","Female", ISBLANK(citizen_services_records_log!H9),"None", citizen_services_records_log!H9 = "Female", "Female", citizen_services_records_log!H9="Male","Male")} -> Female | I9: =IF(OR(ISBLANK(citizen_services_records_log!I9),UPPER(TRIM(citizen_services_records_log!I9))="N/A"),"None",_xlfn.LET(_xlpm.d,RIGHT(SUBSTITUTE(SUBSTITUTE(SUBSTITUTE(SUBSTITUTE(citizen_services_records_log!I9," ",""),"-",""),"(",""),")",""),9),"0"&LEFT(_xlpm.d,2)&" "&MID(_xlpm.d,3,3)&" "&RIGHT(_xlpm.d,4))) -> 074 547 7794 | J9: {=_xlfn.IFS(ISTEXT(citizen_services_records_log!J9),citizen_services_records_log!J9,ISBLANK(citizen_services_records_log!J9),"None")} -> Ward 16 | K9: {=_xlfn.IFS(ISTEXT(citizen_services_records_log!K9),citizen_services_records_log!K9, ISBLANK(citizen_services_records_log!K9),"None")} -> None | L9: {=SUBSTITUTE(PROPER(_xlfn.IFS(ISTEXT(citizen_services_records_log!L9),citizen_services_records_log!L9, ISBLANK(citizen_services_records_log!L9),"None")),"Id","ID",1)} -> Pending Verification | M9: {=IF(citizen_services_records_log!M9 = "Re-opened","Re-opened",PROPER(_xlfn.IFS(ISTEXT(citizen_services_records_log!M9),citizen_services_records_log!M9, ISBLANK(citizen_services_records_log!M9),"None")))} -> Awaiting Documents | N9: {=(_xlfn.IFS(ISTEXT(citizen_services_records_log!N9),citizen_services_records_log!N9,ISBLANK(citizen_services_records_log!N9),"None"))} -> Q096 | O9: {=_xlfn.IFS(ISTEXT(citizen_services_records_log!O9),PROPER(citizen_services_records_log!O9),ISBLANK(citizen_services_records_log!O9),"None")} -> Werner Nel | P9: =IF(ISBLANK(citizen_services_records_log!P9),"None",IF(ISNUMBER(citizen_services_records_log!P9),citizen_services_records_log!P9,DATE(RIGHT(citizen_services_records_log!P9,4),MID(citizen_services_records_log!P9,4,2),LEFT(citizen_services_records_log!P9,2)))) -> 46077 | Q9: {=SUBSTITUTE(_xlfn.IFS(ISTEXT(citizen_services_records_log!Q9),PROPER(citizen_services_records_log!Q9),ISBLANK(citizen_services_records_log!Q9),"None"),"Id","ID",1)} -> None
A10: =IF(ISBLANK(citizen_services_records_log!A10),"None",(CONCATENATE(UPPER(_xlfn.TEXTBEFORE(SUBSTITUTE(citizen_services_records_log!A10, "-", ""), {"0","1","2","3","4","5","6","7","8","9"}, 1)),"-",RIGHT(citizen_services_records_log!A10,6)))) -> DHA-000061 | B10: =IF(ISBLANK(citizen_services_records_log!B10),"None",IF(ISNUMBER(citizen_services_records_log!B10),citizen_services_records_log!B10,DATE(RIGHT(citizen_services_records_log!B10,4),MID(citizen_services_records_log!B10,4,2),LEFT(citizen_services_records_log!B10,2)))) -> 46051 | C10: =IF(citizen_services_records_log!C10 = "SASSA Grant Status Enquiry","SASSA - Grant Status Enquiry",IF(citizen_services_records_log!C10 = "SASSA Grant Application", "SASSA - Grant Application", IF(citizen_services_records_log!C10=0,"None", citizen_services_records_log!C10))) -> Home Affairs - Passport Application | D10: {=_xlfn.IFS(ISTEXT(citizen_services_records_log!D10),PROPER(citizen_services_records_log!D10),ISBLANK(citizen_services_records_log!D10),"None")} -> Three Rivers Clinic | E10: {=_xlfn.IFS(ISTEXT(citizen_services_records_log!E10),PROPER(citizen_services_records_log!E10),ISBLANK(citizen_services_records_log!E10),"None")} -> Nomvula Sithole | F10: {=_xlfn.IFS(ISBLANK(citizen_services_records_log!F10),"None", TYPE(citizen_services_records_log!F10)=1,citizen_services_records_log!F10,citizen_services_records_log!F10="ID NOT PROVIDED","ID not provided" )} -> 7610000000000 | G10: =IF(ISBLANK(citizen_services_records_log!G10),"None",IF(ISNUMBER(citizen_services_records_log!G10),citizen_services_records_log!G10,DATE(RIGHT(citizen_services_records_log!G10,4),MID(citizen_services_records_log!G10,4,2),LEFT(citizen_services_records_log!G10,2)))) -> None | H10: {=_xlfn.IFS(citizen_services_records_log!H10="M", "Male", citizen_services_records_log!H10 = "F", "Female", citizen_services_records_log!H10="male", "Male", citizen_services_records_log!H10="female","Female", ISBLANK(citizen_services_records_log!H10),"None", citizen_services_records_log!H10 = "Female", "Female", citizen_services_records_log!H10="Male","Male")} -> Female | I10: =IF(OR(ISBLANK(citizen_services_records_log!I10),UPPER(TRIM(citizen_services_records_log!I10))="N/A"),"None",_xlfn.LET(_xlpm.d,RIGHT(SUBSTITUTE(SUBSTITUTE(SUBSTITUTE(SUBSTITUTE(citizen_services_records_log!I10," ",""),"-",""),"(",""),")",""),9),"0"&LEFT(_xlpm.d,2)&" "&MID(_xlpm.d,3,3)&" "&RIGHT(_xlpm.d,4))) -> 075 551 5861 | J10: {=_xlfn.IFS(ISTEXT(citizen_services_records_log!J10),citizen_services_records_log!J10,ISBLANK(citizen_services_records_log!J10),"None")} -> Ward 12 | K10: {=_xlfn.IFS(ISTEXT(citizen_services_records_log!K10),citizen_services_records_log!K10, ISBLANK(citizen_services_records_log!K10),"None")} -> None | L10: {=SUBSTITUTE(PROPER(_xlfn.IFS(ISTEXT(citizen_services_records_log!L10),citizen_services_records_log!L10, ISBLANK(citizen_services_records_log!L10),"None")),"Id","ID",1)} -> Incomplete - Missing Proof Of Residence | M10: {=IF(citizen_services_records_log!M10 = "Re-opened","Re-opened",PROPER(_xlfn.IFS(ISTEXT(citizen_services_records_log!M10),citizen_services_records_log!M10, ISBLANK(citizen_services_records_log!M10),"None")))} -> Captured | N10: {=(_xlfn.IFS(ISTEXT(citizen_services_records_log!N10),citizen_services_records_log!N10,ISBLANK(citizen_services_records_log!N10),"None"))} -> Q011 | O10: {=_xlfn.IFS(ISTEXT(citizen_services_records_log!O10),PROPER(citizen_services_records_log!O10),ISBLANK(citizen_services_records_log!O10),"None")} -> Chris Khumalo | P10: =IF(ISBLANK(citizen_services_records_log!P10),"None",IF(ISNUMBER(citizen_services_records_log!P10),citizen_services_records_log!P10,DATE(RIGHT(citizen_services_records_log!P10,4),MID(citizen_services_records_log!P10,4,2),LEFT(citizen_services_records_log!P10,2)))) -> 46075 | Q10: {=SUBSTITUTE(_xlfn.IFS(ISTEXT(citizen_services_records_log!Q10),PROPER(citizen_services_records_log!Q10),ISBLANK(citizen_services_records_log!Q10),"None"),"Id","ID",1)} -> Incorrect ID Number Provided Initially, Corrected
A11: =IF(ISBLANK(citizen_services_records_log!A11),"None",(CONCATENATE(UPPER(_xlfn.TEXTBEFORE(SUBSTITUTE(citizen_services_records_log!A11, "-", ""), {"0","1","2","3","4","5","6","7","8","9"}, 1)),"-",RIGHT(citizen_services_records_log!A11,6)))) -> CLN-000452 | B11: =IF(ISBLANK(citizen_services_records_log!B11),"None",IF(ISNUMBER(citizen_services_records_log!B11),citizen_services_records_log!B11,DATE(RIGHT(citizen_services_records_log!B11,4),MID(citizen_services_records_log!B11,4,2),LEFT(citizen_services_records_log!B11,2)))) -> 46084 | C11: =IF(citizen_services_records_log!C11 = "SASSA Grant Status Enquiry","SASSA - Grant Status Enquiry",IF(citizen_services_records_log!C11 = "SASSA Grant Application", "SASSA - Grant Application", IF(citizen_services_records_log!C11=0,"None", citizen_services_records_log!C11))) -> Clinic - General Consultation | D11: {=_xlfn.IFS(ISTEXT(citizen_services_records_log!D11),PROPER(citizen_services_records_log!D11),ISBLANK(citizen_services_records_log!D11),"None")} -> Vanderbijlpark Home Affairs | E11: {=_xlfn.IFS(ISTEXT(citizen_services_records_log!E11),PROPER(citizen_services_records_log!E11),ISBLANK(citizen_services_records_log!E11),"None")} -> Nomvula Khumalo | F11: {=_xlfn.IFS(ISBLANK(citizen_services_records_log!F11),"None", TYPE(citizen_services_records_log!F11)=1,citizen_services_records_log!F11,citizen_services_records_log!F11="ID NOT PROVIDED","ID not provided" )} -> 4800000000000 | G11: =IF(ISBLANK(citizen_services_records_log!G11),"None",IF(ISNUMBER(citizen_services_records_log!G11),citizen_services_records_log!G11,DATE(RIGHT(citizen_services_records_log!G11,4),MID(citizen_services_records_log!G11,4,2),LEFT(citizen_services_records_log!G11,2)))) -> None | H11: {=_xlfn.IFS(citizen_services_records_log!H11="M", "Male", citizen_services_records_log!H11 = "F", "Female", citizen_services_records_log!H11="male", "Male", citizen_services_records_log!H11="female","Female", ISBLANK(citizen_services_records_log!H11),"None", citizen_services_records_log!H11 = "Female", "Female", citizen_services_records_log!H11="Male","Male")} -> Female | I11: =IF(OR(ISBLANK(citizen_services_records_log!I11),UPPER(TRIM(citizen_services_records_log!I11))="N/A"),"None",_xlfn.LET(_xlpm.d,RIGHT(SUBSTITUTE(SUBSTITUTE(SUBSTITUTE(SUBSTITUTE(citizen_services_records_log!I11," ",""),"-",""),"(",""),")",""),9),"0"&LEFT(_xlpm.d,2)&" "&MID(_xlpm.d,3,3)&" "&RIGHT(_xlpm.d,4))) -> 067 995 6360 | J11: {=_xlfn.IFS(ISTEXT(citizen_services_records_log!J11),citizen_services_records_log!J11,ISBLANK(citizen_services_records_log!J11),"None")} -> Ward 3 (Informal Settlement) | K11: {=_xlfn.IFS(ISTEXT(citizen_services_records_log!K11),citizen_services_records_log!K11, ISBLANK(citizen_services_records_log!K11),"None")} -> None | L11: {=SUBSTITUTE(PROPER(_xlfn.IFS(ISTEXT(citizen_services_records_log!L11),citizen_services_records_log!L11, ISBLANK(citizen_services_records_log!L11),"None")),"Id","ID",1)} -> Complete | M11: {=IF(citizen_services_records_log!M11 = "Re-opened","Re-opened",PROPER(_xlfn.IFS(ISTEXT(citizen_services_records_log!M11),citizen_services_records_log!M11, ISBLANK(citizen_services_records_log!M11),"None")))} -> Re-opened | N11: {=(_xlfn.IFS(ISTEXT(citizen_services_records_log!N11),citizen_services_records_log!N11,ISBLANK(citizen_services_records_log!N11),"None"))} -> Q040 | O11: {=_xlfn.IFS(ISTEXT(citizen_services_records_log!O11),PROPER(citizen_services_records_log!O11),ISBLANK(citizen_services_records_log!O11),"None")} -> None | P11: =IF(ISBLANK(citizen_services_records_log!P11),"None",IF(ISNUMBER(citizen_services_records_log!P11),citizen_services_records_log!P11,DATE(RIGHT(citizen_services_records_log!P11,4),MID(citizen_services_records_log!P11,4,2),LEFT(citizen_services_records_log!P11,2)))) -> None | Q11: {=SUBSTITUTE(_xlfn.IFS(ISTEXT(citizen_services_records_log!Q11),PROPER(citizen_services_records_log!Q11),ISBLANK(citizen_services_records_log!Q11),"None"),"Id","ID",1)} -> System Offline - Captured Manually, Will Upload Later
A12: =IF(ISBLANK(citizen_services_records_log!A12),"None",(CONCATENATE(UPPER(_xlfn.TEXTBEFORE(SUBSTITUTE(citizen_services_records_log!A12, "-", ""), {"0","1","2","3","4","5","6","7","8","9"}, 1)),"-",RIGHT(citizen_services_records_log!A12,6)))) -> DHA-000449 | B12: =IF(ISBLANK(citizen_services_records_log!B12),"None",IF(ISNUMBER(citizen_services_records_log!B12),citizen_services_records_log!B12,DATE(RIGHT(citizen_services_records_log!B12,4),MID(citizen_services_records_log!B12,4,2),LEFT(citizen_services_records_log!B12,2)))) -> 46000 | C12: =IF(citizen_services_records_log!C12 = "SASSA Grant Status Enquiry","SASSA - Grant Status Enquiry",IF(citizen_services_records_log!C12 = "SASSA Grant Application", "SASSA - Grant Application", IF(citizen_services_records_log!C12=0,"None", citizen_services_records_log!C12))) -> Home Affairs - Death Certificate | D12: {=_xlfn.IFS(ISTEXT(citizen_services_records_log!D12),PROPER(citizen_services_records_log!D12),ISBLANK(citizen_services_records_log!D12),"None")} -> Meyerton Municipal Office | E12: {=_xlfn.IFS(ISTEXT(citizen_services_records_log!E12),PROPER(citizen_services_records_log!E12),ISBLANK(citizen_services_records_log!E12),"None")} -> Zodwa Steyn | F12: {=_xlfn.IFS(ISBLANK(citizen_services_records_log!F12),"None", TYPE(citizen_services_records_log!F12)=1,citizen_services_records_log!F12,citizen_services_records_log!F12="ID NOT PROVIDED","ID not provided" )} -> 4800000000000 | G12: =IF(ISBLANK(citizen_services_records_log!G12),"None",IF(ISNUMBER(citizen_services_records_log!G12),citizen_services_records_log!G12,DATE(RIGHT(citizen_services_records_log!G12,4),MID(citizen_services_records_log!G12,4,2),LEFT(citizen_services_records_log!G12,2)))) -> 17620 | H12: {=_xlfn.IFS(citizen_services_records_log!H12="M", "Male", citizen_services_records_log!H12 = "F", "Female", citizen_services_records_log!H12="male", "Male", citizen_services_records_log!H12="female","Female", ISBLANK(citizen_services_records_log!H12),"None", citizen_services_records_log!H12 = "Female", "Female", citizen_services_records_log!H12="Male","Male")} -> Male | I12: =IF(OR(ISBLANK(citizen_services_records_log!I12),UPPER(TRIM(citizen_services_records_log!I12))="N/A"),"None",_xlfn.LET(_xlpm.d,RIGHT(SUBSTITUTE(SUBSTITUTE(SUBSTITUTE(SUBSTITUTE(citizen_services_records_log!I12," ",""),"-",""),"(",""),")",""),9),"0"&LEFT(_xlpm.d,2)&" "&MID(_xlpm.d,3,3)&" "&RIGHT(_xlpm.d,4))) -> 067 990 1527 | J12: {=_xlfn.IFS(ISTEXT(citizen_services_records_log!J12),citizen_services_records_log!J12,ISBLANK(citizen_services_records_log!J12),"None")} -> Ward 15 | K12: {=_xlfn.IFS(ISTEXT(citizen_services_records_log!K12),citizen_services_records_log!K12, ISBLANK(citizen_services_records_log!K12),"None")} -> None | L12: {=SUBSTITUTE(PROPER(_xlfn.IFS(ISTEXT(citizen_services_records_log!L12),citizen_services_records_log!L12, ISBLANK(citizen_services_records_log!L12),"None")),"Id","ID",1)} -> Awaiting Home Affairs Confirmation | M12: {=IF(citizen_services_records_log!M12 = "Re-opened","Re-opened",PROPER(_xlfn.IFS(ISTEXT(citizen_services_records_log!M12),citizen_services_records_log!M12, ISBLANK(citizen_services_records_log!M12),"None")))} -> Re-opened | N12: {=(_xlfn.IFS(ISTEXT(citizen_services_records_log!N12),citizen_services_records_log!N12,ISBLANK(citizen_services_records_log!N12),"None"))} -> Q075 | O12: {=_xlfn.IFS(ISTEXT(citizen_services_records_log!O12),PROPER(citizen_services_records_log!O12),ISBLANK(citizen_services_records_log!O12),"None")} -> Marius Swart | P12: =IF(ISBLANK(citizen_services_records_log!P12),"None",IF(ISNUMBER(citizen_services_records_log!P12),citizen_services_records_log!P12,DATE(RIGHT(citizen_services_records_log!P12,4),MID(citizen_services_records_log!P12,4,2),LEFT(citizen_services_records_log!P12,2)))) -> 46013 | Q12: {=SUBSTITUTE(_xlfn.IFS(ISTEXT(citizen_services_records_log!Q12),PROPER(citizen_services_records_log!Q12),ISBLANK(citizen_services_records_log!Q12),"None"),"Id","ID",1)} -> Biometric Capture Failed, Rescheduled
